Traceback (most recent call last):
  File "/opt/hostedtoolcache/Python/3.9.16/x64/lib/python3.9/site-packages/jupyter_cache/executors/utils.py", line 51, in single_nb_execution
    executenb(
  File "/opt/hostedtoolcache/Python/3.9.16/x64/lib/python3.9/site-packages/nbclient/client.py", line 1204, in execute
    return NotebookClient(nb=nb, resources=resources, km=km, **kwargs).execute()
  File "/opt/hostedtoolcache/Python/3.9.16/x64/lib/python3.9/site-packages/nbclient/util.py", line 84, in wrapped
    return just_run(coro(*args, **kwargs))
  File "/opt/hostedtoolcache/Python/3.9.16/x64/lib/python3.9/site-packages/nbclient/util.py", line 62, in just_run
    return loop.run_until_complete(coro)
  File "/opt/hostedtoolcache/Python/3.9.16/x64/lib/python3.9/asyncio/base_events.py", line 647, in run_until_complete
    return future.result()
  File "/opt/hostedtoolcache/Python/3.9.16/x64/lib/python3.9/site-packages/nbclient/client.py", line 663, in async_execute
    await self.async_execute_cell(
  File "/opt/hostedtoolcache/Python/3.9.16/x64/lib/python3.9/site-packages/nbclient/client.py", line 965, in async_execute_cell
    await self._check_raise_for_error(cell, cell_index, exec_reply)
  File "/opt/hostedtoolcache/Python/3.9.16/x64/lib/python3.9/site-packages/nbclient/client.py", line 862, in _check_raise_for_error
    raise CellExecutionError.from_cell_and_msg(cell, exec_reply_content)
nbclient.exceptions.CellExecutionError: An error occurred while executing the following cell:
------------------
# Read all data
data_least_squares = np.load('refinement_results/least_squares.npy', allow_pickle=True).item()
data_bumps = np.load('refinement_results/bumps_dream_steps20000_burn1000_pop4.npy', allow_pickle=True).item()
data_emcee = np.load('refinement_results/emcee_steps20000_walkers40.npy', allow_pickle=True).item()
------------------

[0;31m---------------------------------------------------------------------------[0m
[0;31mFileNotFoundError[0m                         Traceback (most recent call last)
Cell [0;32mIn[2], line 2[0m
[1;32m      1[0m [38;5;66;03m# Read all data[39;00m
[0;32m----> 2[0m data_least_squares [38;5;241m=[39m [43mnp[49m[38;5;241;43m.[39;49m[43mload[49m[43m([49m[38;5;124;43m'[39;49m[38;5;124;43mrefinement_results/least_squares.npy[39;49m[38;5;124;43m'[39;49m[43m,[49m[43m [49m[43mallow_pickle[49m[38;5;241;43m=[39;49m[38;5;28;43;01mTrue[39;49;00m[43m)[49m[38;5;241m.[39mitem()
[1;32m      3[0m data_bumps [38;5;241m=[39m np[38;5;241m.[39mload([38;5;124m'[39m[38;5;124mrefinement_results/bumps_dream_steps20000_burn1000_pop4.npy[39m[38;5;124m'[39m, allow_pickle[38;5;241m=[39m[38;5;28;01mTrue[39;00m)[38;5;241m.[39mitem()
[1;32m      4[0m data_emcee [38;5;241m=[39m np[38;5;241m.[39mload([38;5;124m'[39m[38;5;124mrefinement_results/emcee_steps20000_walkers40.npy[39m[38;5;124m'[39m, allow_pickle[38;5;241m=[39m[38;5;28;01mTrue[39;00m)[38;5;241m.[39mitem()

File [0;32m/opt/hostedtoolcache/Python/3.9.16/x64/lib/python3.9/site-packages/numpy/lib/npyio.py:405[0m, in [0;36mload[0;34m(file, mmap_mode, allow_pickle, fix_imports, encoding, max_header_size)[0m
[1;32m    403[0m     own_fid [38;5;241m=[39m [38;5;28;01mFalse[39;00m
[1;32m    404[0m [38;5;28;01melse[39;00m:
[0;32m--> 405[0m     fid [38;5;241m=[39m stack[38;5;241m.[39menter_context([38;5;28;43mopen[39;49m[43m([49m[43mos_fspath[49m[43m([49m[43mfile[49m[43m)[49m[43m,[49m[43m [49m[38;5;124;43m"[39;49m[38;5;124;43mrb[39;49m[38;5;124;43m"[39;49m[43m)[49m)
[1;32m    406[0m     own_fid [38;5;241m=[39m [38;5;28;01mTrue[39;00m
[1;32m    408[0m [38;5;66;03m# Code to distinguish from NumPy binary files and pickles.[39;00m

[0;31mFileNotFoundError[0m: [Errno 2] No such file or directory: 'refinement_results/least_squares.npy'
FileNotFoundError: [Errno 2] No such file or directory: 'refinement_results/least_squares.npy'

